Workbook

Sheet START HERE
B2: Deerfield Intelligence | Operational Gap Assessment Tool
B4: Purpose: capture interview evidence once, then automatically carry it through triangulation → prioritization → sequencing.
B6: STAGE | C6: TAB | D6: WHAT YOU DO | E6: WHAT THE TOOL DOES
B7: 1. Listen | C7: 1_Evidence Log | D7: During / post interviews, add one observation per row | E7: Creates a structured evidence base with issue tags, source, evidence type and initial hypothesis.
B8: 2. Diagnose & Validate | C8: 2_Issue Register | D8: Define each emerging issue once and enter a few judgment calls (confidence, root cause, impact). | E8: Pulls interview counts, unique sources and corroborating evidence from the log; flags signal strength.
B9: 3. Prioritize | D9: Score business impact, urgency, scale dependency and effort on 1–5 scales. | E9: Calculates a weighted priority score and assigns a priority band.
B10: 4. Sequence | D10: Enter dependency, owner and timing logic. | E10: Suggests Now / Next / Later based on priority and readiness; creates the 90-day action queue.
B11: 5. Output | C11: 3_Sequence View | D11: Review output | E11: Creates final snapshot of triangulation > prioritization > sequencing
B13: Scoring guide (keep it directional — this is a decision aid, not false precision)
B15: Dimension | C15: 1 | D15: 3 | E15: 5
B16: Business impact | C16: Localized inconvenience | D16: Meaningful drag on a pod/function | E16: Material risk to DI scaling, delivery, controls or talent
B17: Urgency | C17: Can wait >6 months | D17: Should address this quarter | E17: Immediate / compounding risk
B18: Scale dependency | C18: Works similarly at 30 people | D18: Will become harder as team grows | E18: Likely breaks before / during 10→30 scale
B19: Effort | C19: Days / simple fix | D19: Several weeks / cross-functional | E19: Multi-month / complex dependency
B21: *Unique Sources helper is pre-wired to the named interviewees in the scenario. If you interview different people, replace those names
B22: in the formula or use the evidence count + your judgment; the tool is intentionally lightweight.

Sheet 1_Evidence Log
B2: Obs ID | C2: Interview / Source | D2: Role / Group | E2: Date | F2: Issue ID | G2: Category | H2: Observation | I2: Example / Evidence | J2: Evidence Type | K2: Initial Hypothesis | L2: Severity (1-5) | M2: Confidence | N2: Notes
B3: OBS-001 | C3: Elena Rodriguez | D3: HR / Central Function | E3: 2026-09-18 | F3: ORG-01 | G3: Operating Model & Decision Rights | H3: HR support for DI is capacity-constrained and largely reactive. | I3: Elena estimates only 20–25% of her time is available for DI; coordination is mainly a monthly meeting with David, after issues have already occurred. | J3: Metric / data | K3: DI lacks a sufficiently frequent HR–Operations interface and a counterpart who can translate team needs into central processes. | L3: 4 | M3: High | N3: Elena's capacity estimate and current cadence; validate with David and DI leads.
B4: =IF(C4="","","OBS-"&TEXT(ROW()-2,"000")) -> OBS-002 | C4: Elena Rodriguez | D4: HR / Central Function | E4: 2026-09-18 | F4: WFP-01 | G4: Workforce Planning | H4: DI does not have a clear, sequenced workforce plan for growth from 10 to 30. | I4: HR has no roadmap specifying roles, timing or sequence; searches can change level or skill profile after sourcing begins, and some stall when projects are deprioritized. | J4: Repeated pattern | K4: Workforce needs are triggered reactively by immediate project pressure rather than an agreed capacity and capability plan. | L4: 5 | M4: High | N4: Strong single-source pattern; validate frequency and examples with David and pod leads.
B5: =IF(C5="","","OBS-"&TEXT(ROW()-2,"000")) -> OBS-003 | C5: Elena Rodriguez | D5: HR / Central Function | E5: 2026-09-18 | F5: HIR-01 | G5: Hiring | H5: The recruiting process is too slow and ad hoc to support planned hiring volume. | I5: A recent ML engineer search took four months; two strong candidates were lost because DI could not provide a timeline. | J5: Direct example | K5: DI lacks a standardized, actively managed recruiting funnel with clear stages, service levels and candidate ownership. | L5: 5 | M5: High | N5: Material quantitative example; seek ATS data to confirm baseline cycle time and conversion.
B6: =IF(C6="","","OBS-"&TEXT(ROW()-2,"000")) -> OBS-004 | C6: Elena Rodriguez | D6: HR / Central Function | E6: 2026-09-18 | F6: HIR-01 | G6: Hiring | H6: Interview scheduling and stage-by-stage execution create avoidable delay. | I6: It typically takes one to two weeks to secure three to four interview slots; rounds are booked sequentially and feedback waits add further gaps. | J6: Metric / data | K6: Unreserved interviewer capacity, sequential scheduling and unclear execution ownership extend time-to-hire. | L6: 4 | M6: High | N6: Specific timing estimate from process owner; validate against recent requisitions.
B7: =IF(C7="","","OBS-"&TEXT(ROW()-2,"000")) -> OBS-005 | C7: Elena Rodriguez | D7: HR / Central Function | E7: 2026-09-18 | F7: HIR-01 | G7: Hiring | H7: David is a single point of dependency for hiring decisions and final interviews. | I7: David makes the final call on every hire; when his calendar is constrained, Intelligence recruiting stops even when the team supports a candidate. | J7: Repeated pattern | K7: Hiring decision rights have not been delegated or supported by a sufficiently trusted assessment process. | L7: 5 | M7: Medium | N7: Elena's recurring observation; test David's rationale and appetite to delegate by role level.
B8: =IF(C8="","","OBS-"&TEXT(ROW()-2,"000")) -> OBS-006 | C8: Elena Rodriguez | D8: HR / Central Function | E8: 2026-09-18 | G8: Strength / Context | H8: DI's hiring model preserves a strong quality bar and is effective at closing candidates once they meet the team. | I8: Elena reports candidates are impressed by David, the team and the work; David is decisive once engaged, and engineers protect technical and cultural standards. | J8: Perception / opinion | K8: The recruiting redesign should preserve the close and hiring bar while removing upstream planning and execution friction. | L8: 3 | M8: Medium | N8: Positive context only; excluded from issue counts and retained to define what the redesign must preserve.
B9: =IF(C9="","","OBS-"&TEXT(ROW()-2,"000")) -> OBS-007 | C9: Elena Rodriguez | D9: HR / Central Function | E9: 2026-09-18 | F9: ONB-01 | G9: Onboarding | H9: Technical onboarding lacks an end-to-end owner and standard access checklist. | I9: One new hire could not access the code repository for three weeks; hardware, base accounts and specialized access are split across IT and different DI team members. | J9: Direct example | K9: Fragmented provisioning ownership and tribal knowledge prevent new hires from becoming productive quickly. | L9: 5 | M9: High | N9: Concrete example; validate whether this occurred once or reflects typical access lead times.
B10: =IF(C10="","","OBS-"&TEXT(ROW()-2,"000")) -> OBS-008 | C10: Elena Rodriguez | D10: HR / Central Function | E10: 2026-09-18 | F10: ONB-02 | G10: Onboarding | H10: New hires lack a structured first-30-day plan and integration into the broader firm. | I10: After standard HR orientation, new hires largely 'sink or swim'; there is no formal 30-60-90 plan or stakeholder map, and they remain socially and operationally isolated from Deerfield. | J10: Repeated pattern | K10: DI onboarding covers basic administration but not role ramp-up, organizational context or cross-firm relationships. | L10: 4 | M10: Medium | N10: Elena's assessment; test directly with recent hires and managers.
B11: =IF(C11="","","OBS-"&TEXT(ROW()-2,"000")) -> OBS-009 | C11: Elena Rodriguez | D11: HR / Central Function | E11: 2026-09-18 | F11: WFP-02 | G11: Workforce Planning | H11: DI's flat structure will not scale to 30 people without a capable middle layer. | I11: Most employees currently rely on David; Elena expects pod or functional leads, explicit spans of control and manager training will be needed before the team reaches roughly 15–20. | J11: Perception / opinion | K11: DI has not yet designed the leadership structure and management capability required for the next stage of growth. | L11: 5 | M11: Medium | N11: Forward-looking risk rather than a current failure; validate against current reporting lines and hiring plan.
B12: =IF(C12="","","OBS-"&TEXT(ROW()-2,"000")) -> OBS-010 | C12: Elena Rodriguez | D12: HR / Central Function | E12: 2026-09-18 | F12: ORG-01 | G12: Organization & Performance | H12: Roles, accountabilities and decision rights are informal and sometimes ambiguous. | I12: Elena believes different team members could name different owners for the same data pipeline or product feature; in-seat expectations are not documented beyond titles. | J12: Perception / opinion | K12: Scrappy shared ownership is obscuring accountability and will create duplication, escalation and performance-management difficulty as DI grows. | L12: 4 | M12: Medium | N12: Hypothesis requires corroboration from delivery examples and pod interviews.
B13: =IF(C13="","","OBS-"&TEXT(ROW()-2,"000")) -> OBS-011 | C13: Elena Rodriguez | D13: HR / Central Function | E13: 2026-09-18 | F13: ORG-02 | G13: Organization & Performance | H13: Performance management is informal and insufficiently documented. | I13: Firm-wide reviews are treated as a check-box exercise; feedback is mainly verbal, leaving limited support for compensation differentiation, promotion decisions or performance action. | J13: Repeated pattern | K13: DI has not adapted the firm's performance framework into a lightweight process that fits an agile technical team. | L13: 4 | M13: Medium | N13: Validate employee experience and review completion/document quality.
B14: =IF(C14="","","OBS-"&TEXT(ROW()-2,"000")) -> OBS-012 | C14: Elena Rodriguez | D14: HR / Central Function | E14: 2026-09-18 | F14: WFP-03 | G14: Workforce Planning | H14: Levels and career paths are not defined for DI technical talent. | I14: There is no documented progression from Senior to Staff or Lead and no competency matrix; advancement depends heavily on David's judgment and visibility. | J14: Perception / opinion | K14: Lack of transparent growth paths may become a retention risk as the team expands, despite strong current culture and talent quality. | L14: 4 | M14: Medium | N14: Emerging risk, not evidence of current attrition; test with employees and exit/engagement data.
B15: =IF(C15="","","OBS-"&TEXT(ROW()-2,"000")) -> OBS-013 | C15: Elena Rodriguez | D15: HR / Central Function | E15: 2026-09-18 | F15: INT-01 | G15: DI-Deerfield Integration | H15: DI operates as a silo from the traditional investment organization, weakening shared context and support for resource requests. | I15: Elena observes an 'us versus them' dynamic, limited positive touchpoints and weak visibility into DI's value; she links this to harder approval of compensation and resources. | J15: Perception / opinion | K15: DI lacks a deliberate stakeholder-engagement and value-communication mechanism with the broader firm. | L15: 4 | M15: Medium | N15: Important but perception-led; test with investment stakeholders and examples of delayed or rejected requests.
B16: =IF(C16="","","OBS-"&TEXT(ROW()-2,"000")) -> OBS-014 | C16: Elena Rodriguez | D16: HR / Central Function | E16: 2026-09-18 | F16: ORG-03 | G16: Organization & Performance | H16: Annual compensation cycles limit DI's ability to respond to fast-moving retention risks. | I16: When a key engineer receives a competing offer mid-year, Elena must pursue an out-of-cycle adjustment through an exception process. | J16: Repeated pattern | K16: DI lacks a defined, evidence-based path for time-sensitive compensation decisions outside the annual cycle. | L16: 4 | M16: Medium | N16: Separate compensation issue; validate frequency, decision time and outcomes with HR and the Compensation Committee.
B17: =IF(C17="","","OBS-"&TEXT(ROW()-2,"000")) -> OBS-015 | C17: Elena Rodriguez | D17: HR / Central Function | E17: 2026-09-18 | F17: WFP-04 | G17: Workforce Planning | H17: Firm-wide titles and pay bands do not map cleanly to DI's technical roles. | I17: Traditional definitions of Vice President, Director and Senior Associate do not consistently reflect technology-market titles, responsibilities or compensation. | J17: Repeated pattern | K17: DI lacks a technology-specific job architecture mapped back to Deerfield's firm-wide levels and compensation framework. | L17: 4 | M17: Medium | N17: Separate job-architecture issue; validate with current role mapping and external benchmarks.
B18: =IF(C18="","","OBS-"&TEXT(ROW()-2,"000")) -> OBS-016 | C18: Elena Rodriguez | D18: HR / Central Function | E18: 2026-09-18 | F18: CORP-01 | G18: Corporate Interfaces | H18: Standard procurement processes can delay access to specialized software and data tools. | I18: Elena reports that approval of a new tool or specialized data subscription can take weeks through standard corporate channels. | J18: Repeated pattern | K18: DI lacks a proportionate, clearly routed approval path for time-sensitive technology and data purchases. | L18: 4 | M18: Medium | N18: Separate procurement issue; triangulate with IT/SecOps and Finance/Procurement.
B19: =IF(C19="","","OBS-"&TEXT(ROW()-2,"000")) -> OBS-017 | C19: Elena Rodriguez | D19: HR / Central Function | E19: 2026-09-18 | F19: HIR-02 | G19: Hiring | H19: Firm-wide office expectations may constrain DI's access to specialized AI talent. | I19: DI competes with employers offering fully remote roles, making office-location expectations a recurring point of negotiation with candidates. | J19: Repeated pattern | K19: DI has not defined when talent scarcity justifies role-specific flexibility within Deerfield's workplace policy. | L19: 3 | M19: Medium | N19: Separate hiring-policy issue; validate actual candidate losses and role/location requirements.
B20: =IF(C20="","","OBS-"&TEXT(ROW()-2,"000")) -> OBS-018 | C20: Elena Rodriguez | D20: HR / Central Function | E20: 2026-09-18 | F20: ORG-01 | G20: Operating Model & Decision Rights | H20: Ownership between HR and DI is blurred, creating handoffs and work in the wrong function. | I20: HR coordinates technical interview calendars and is asked to ensure technical setup, while DI sometimes handles compensation guidance or performance issues without early HR involvement. | J20: Repeated pattern | K20: DI needs a single operational front door with explicit decision rights: Operations owns team context and execution; HR owns framework, fairness, compliance and sensitive employee matters. | L20: 4 | M20: High | N20: Elena proposed a weekly tactical sync and shared tracker as the working interface.
B21: =IF(C21="","","OBS-"&TEXT(ROW()-2,"000")) -> OBS-019 | C21: James Okonkwo | D21: Finance / Central Function | E21: 2026-09-18 | G21: Strength / Context | H21: DI is viewed as cost-conscious, and David engages constructively on financial trade-offs. | I21: James reports that the team is thoughtful about proposed purchases and that David listens when Finance challenges spend. | J21: Perception / opinion | K21: The finance operating model should improve visibility and control without assuming DI is culturally undisciplined about cost. | L21: 3 | M21: Medium | N21: Positive context only; excluded from issue counts and retained to define what the redesign must preserve.
B22: =IF(C22="","","OBS-"&TEXT(ROW()-2,"000")) -> OBS-020 | C22: James Okonkwo | D22: Finance / Central Function | E22: 2026-09-18 | F22: FIN-01 | G22: Financial Planning & Spend Management | H22: DI's annual budget is based on rough historical estimates rather than a costed delivery and growth roadmap. | I22: The budget uses prior-year spend plus buffers for hiring, data and cloud; new projects and their resource needs are not translated into line items before work begins. | J22: Repeated pattern | K22: DI lacks a rolling driver-based financial model connecting headcount, roadmap choices and major technology consumption to expected spend. | L22: 5 | M22: High | N22: Corroborate with the current budget model, hiring plan and project roadmap.
B23: =IF(C23="","","OBS-"&TEXT(ROW()-2,"000")) -> OBS-021 | C23: James Okonkwo | D23: Finance / Central Function | E23: 2026-09-18 | F23: FIN-01 | G23: Financial Planning & Spend Management | H23: Finance receives too little forward visibility to forecast DI's major spending needs. | I23: James wants a rolling six-month outlook and 30–60 days' notice for major expenses; current visibility is often about two weeks and triggered by urgent payment requests. | J23: Metric / data | K23: DI lacks a regular reforecasting process and a mechanism for translating roadmap changes into financial implications. | L23: 5 | M23: High | N23: Specific current- and future-state timing from the Finance liaison; validate with recent requests.
B24: =IF(C24="","","OBS-"&TEXT(ROW()-2,"000")) -> OBS-022 | C24: James Okonkwo | D24: Finance / Central Function | E24: 2026-09-18 | F24: FIN-02 | G24: Financial Planning & Spend Management | H24: Cloud spend is monitored too late to prevent material budget variance. | I24: DI finished the prior quarter approximately 40% over its cloud budget, and Finance identified the overage only after the quarter had ended. | J24: Direct example | K24: DI lacks timely cloud-cost monitoring, thresholds and accountable operational follow-up during the reporting period. | L24: 5 | M24: High | N24: Direct quantified example; validate against AWS/GCP billing and the quarterly forecast.
B25: =IF(C25="","","OBS-"&TEXT(ROW()-2,"000")) -> OBS-023 | C25: James Okonkwo | D25: Finance / Central Function | E25: 2026-09-18 | F25: FIN-02 | G25: Financial Planning & Spend Management | H25: DI's cloud-cost exposure can change rapidly without an early-warning mechanism. | I25: AWS and GCP currently cost about $30,000 per month; James believes usage can double quickly when new infrastructure is launched or large jobs continue running. | J25: Metric / data | K25: Variable infrastructure consumption is not paired with weekly burn-rate monitoring, anomaly alerts or named ownership for investigating spikes. | L25: 5 | M25: High | N25: Current spend estimate plus risk assessment; triangulate with technical owners and cloud-cost data.
B26: =IF(C26="","","OBS-"&TEXT(ROW()-2,"000")) -> OBS-024 | C26: James Okonkwo | D26: Finance / Central Function | E26: 2026-09-18 | F26: BVC-01 | G26: Business Case & Value Management | H26: DI cannot consistently attribute spend to projects or workstreams. | I26: Data, cloud and other costs are largely reported in aggregate, so Finance cannot explain which initiatives caused increases or whether the spend was worthwhile. | J26: Repeated pattern | K26: DI lacks project-level cost allocation and a lightweight method for linking consumption to the work that generated it. | L26: 4 | M26: High | N26: Validate feasible allocation granularity with Finance and technical leads; avoid false precision.
B27: =IF(C27="","","OBS-"&TEXT(ROW()-2,"000")) -> OBS-025 | C27: James Okonkwo | D27: Finance / Central Function | E27: 2026-09-18 | F27: BVC-01 | G27: Business Case & Value Management | H27: Partner reporting describes DI's inputs and costs but does not connect them to business or investment outcomes. | I27: Current reporting lists salaries, data and cloud costs; partners are beginning to ask what several million dollars of annual spend is buying and whether specific data investments improved decisions. | J27: Repeated pattern | K27: DI lacks a value narrative and supporting measures that connect major investments to delivery, investment insight or portfolio impact. | L27: 5 | M27: Medium | N27: Partner questions are reported by James; validate directly with partners and avoid claiming causal investment returns without evidence.
B28: =IF(C28="","","OBS-"&TEXT(ROW()-2,"000")) -> OBS-026 | C28: James Okonkwo | D28: Finance / Central Function | E28: 2026-09-18 | F28: CORP-01 | G28: Corporate Interfaces | H28: New tools and vendor commitments can be initiated before Finance reviews the need, budget or terms. | I28: Team members may start a subscription or free trial and Finance learns of the commitment only when an invoice or credit-card charge appears. | J28: Repeated pattern | K28: DI lacks a proportionate pre-commitment intake and approval path that is fast enough for the team to use consistently. | L28: 5 | M28: High | N28: Corroborates Elena's concern that the standard path does not fit DI, while showing the resulting bypass behavior.
B29: =IF(C29="","","OBS-"&TEXT(ROW()-2,"000")) -> OBS-027 | C29: James Okonkwo | D29: Finance / Central Function | E29: 2026-09-18 | F29: CORP-01 | G29: Corporate Interfaces | H29: Procurement authority and approval thresholds are unclear. | I29: James cannot identify who may approve a $5,000 annual tool or when Finance's receipt of an invoice becomes the de facto approval point. | J29: Direct example | K29: Decision rights and spend thresholds are not explicit across DI Operations, technical leaders, Finance and the corporate CFO. | L29: 5 | M29: High | N29: Direct ownership gap; validate current delegation-of-authority policy before designing thresholds.
B30: =IF(C30="","","OBS-"&TEXT(ROW()-2,"000")) -> OBS-028 | C30: James Okonkwo | D30: Finance / Central Function | E30: 2026-09-18 | F30: VEN-01 | G30: Vendor & Contract Management | H30: DI has duplicate and potentially underused vendor subscriptions. | I30: Finance found three data-visualization tools being paid for simultaneously because different employees had established them at different times. | J30: Direct example | K30: DI lacks a complete vendor inventory, usage review and periodic rationalization process. | L30: 4 | M30: High | N30: Concrete overlap example; a full vendor audit would establish the scale of waste.
B31: =IF(C31="","","OBS-"&TEXT(ROW()-2,"000")) -> OBS-029 | C31: James Okonkwo | D31: Finance / Central Function | E31: 2026-09-18 | F31: VEN-01 | G31: Vendor & Contract Management | H31: Vendor contracts and commercial terms are fragmented across people and locations. | I31: James has found contracts signed by former employees and has had to investigate who authorized them, whether the tools remain in use and when they renew. | J31: Repeated pattern | K31: DI lacks a centralized contract repository with current business owners, costs, terms and renewal dates. | L31: 5 | M31: High | N31: Recurring observation from the person performing the manual reconciliation.
B32: =IF(C32="","","OBS-"&TEXT(ROW()-2,"000")) -> OBS-030 | C32: James Okonkwo | D32: Finance / Central Function | E32: 2026-09-18 | F32: VEN-01 | G32: Vendor & Contract Management | H32: DI is exposed to avoidable renewal and termination risk. | I32: Large data contracts can require 90 days' notice, creating a risk of default renewal when ownership is unclear or cancellation windows are missed. | J32: Repeated pattern | K32: Vendor lifecycle management does not reliably trigger timely usage, value and renewal decisions. | L32: 4 | M32: High | N32: Validate notice periods and auto-renewal exposure through the contract audit.
B33: =IF(C33="","","OBS-"&TEXT(ROW()-2,"000")) -> OBS-031 | C33: James Okonkwo | D33: Finance / Central Function | E33: 2026-09-18 | F33: VEN-01 | G33: Vendor & Contract Management | H33: Business ownership for vendors is unclear, causing renewal by default. | I33: For a data-provider renewal, Finance may be redirected among David, Priya and Marcus without anyone clearly accountable for deciding whether the service is still required. | J33: Direct example | K33: DI has not assigned one accountable business owner for each vendor relationship and renewal decision. | L33: 4 | M33: High | N33: Specific decision-path example; test whether it recurs across the vendor portfolio.
... B36: =IF(C36="","","OBS-"&TEXT(ROW()-2,"000")) -> OBS-034 | C36: James Okonkwo | D36: Finance / Central Function | E36: 2026-09-18 | F36: FIN-01 | G36: Financial Planning & Spend Management | H36: The current finance-control model depends on manual effort that will not scale. | I36: James spends about 20% of his time on DI and estimates a personally enforced manual gatekeeping workaround would remain viable for only three to six months or until roughly 15–20 employees. | J36: Metric / data | K36: Without an Operations owner and shared controls, Finance cannot absorb the additional coordination and monitoring load created by growth to 30. | L36: 5 | M36: High | N36: Specific capacity and scalability estimate from the Finance liaison.
B37: =IF(C37="","","OBS-"&TEXT(ROW()-2,"000")) -> OBS-035 | C37: Marcus Thompson | D37: Portfolio Enablement Pod | E37: 2026-09-18 | G37: Strength / Context | H37: Marcus's pod combines direct portfolio-company access, strong technical autonomy and rapid delivery. | I37: Deerfield's investor relationship gives the pod access to portfolio executives; David does not micromanage technical decisions, and Marcus cited a tool that accelerated a clinical-trial process by 30%. | J37: Direct example | K37: The operating model should add coordination and predictability while preserving direct client access, technical autonomy and speed. | L37: 4 | M37: Medium | N37: Positive context only; excluded from issue counts and retained to define what the redesign must preserve.
B38: =IF(C38="","","OBS-"&TEXT(ROW()-2,"000")) -> OBS-036 | C38: Marcus Thompson | D38: Portfolio Enablement Pod | E38: 2026-09-18 | F38: PIP-01 | G38: Portfolio Intake & Prioritization | H38: DI lacks a controlled front door for portfolio-support requests. | I38: Requests arrive through Partners, Principals, portfolio-company executives, David or informal Slack messages; there is no consistent evaluation or intake step. | J38: Repeated pattern | K38: Open access without structured intake prevents DI from comparing demand against strategy, impact and available capacity. | L38: 5 | M38: High | N38: Validate request volume and channels with Investment Partners and David.
B39: =IF(C39="","","OBS-"&TEXT(ROW()-2,"000")) -> OBS-037 | C39: Marcus Thompson | D39: Portfolio Enablement Pod | E39: 2026-09-18 | F39: PIP-01 | G39: Portfolio Intake & Prioritization | H39: Competing requests are resolved through urgency and influence rather than explicit trade-offs. | I39: Marcus described prioritization as 'loudest voice wins'; urgent work displaces planned work without a formal decision or communication to the affected stakeholder. | J39: Repeated pattern | K39: DI lacks transparent prioritization criteria and a mechanism for making and communicating trade-off decisions. | L39: 5 | M39: High | N39: Strong repeated pattern; triangulate how David and Investment Partners perceive current prioritization.
B40: =IF(C40="","","OBS-"&TEXT(ROW()-2,"000")) -> OBS-038 | C40: Marcus Thompson | D40: Portfolio Enablement Pod | E40: 2026-09-18 | F40: PIP-01 | G40: Portfolio Intake & Prioritization | H40: Urgent requests create material disruption beyond their initial estimate. | I40: A two-day physician-targeting request expanded to two weeks, stalled a rare-disease patient-matching project, frustrated the original company and required ten days of late work to recover. | J40: Direct example | K40: DI accepts urgent work without adequately testing scope, dependency and displacement consequences. | L40: 5 | M40: High | N40: Concrete displacement example supporting the intake and trade-off issue.
B41: =IF(C41="","","OBS-"&TEXT(ROW()-2,"000")) -> OBS-039 | C41: Marcus Thompson | D41: Portfolio Enablement Pod | E41: 2026-09-18 | F41: SCP-01 | G41: Scoping & Delivery | H41: Projects begin without sufficiently clear scope, stakeholder obligations or a definition of done. | I41: One six-week engagement expanded to fourteen weeks; initial releases are followed by repeated feature requests and a long tail of support because completion criteria were not agreed. | J41: Direct example | K41: DI lacks a lightweight engagement charter defining outcomes, boundaries, milestones, client inputs and transition or exit criteria. | L41: 5 | M41: High | N41: Separate from prioritization: this concerns how accepted work is scoped and closed.
B42: =IF(C42="","","OBS-"&TEXT(ROW()-2,"000")) -> OBS-040 | C42: Marcus Thompson | D42: Portfolio Enablement Pod | E42: 2026-09-18 | F42: CAP-01 | G42: Capacity Planning | H42: Pod capacity and delivery commitments are based largely on judgment rather than visible workload data. | I42: Marcus cannot readily quantify time by project or see whether Priya's pod is at 50% or 150% capacity; commitments are made before cross-pod capacity is known. | J42: Repeated pattern | K42: DI lacks a shared, sufficiently lightweight capacity view to support credible commitments and data-backed trade-offs. | L42: 5 | M42: High | N42: Validate what utilization data can be captured without burdensome time tracking.
B43: =IF(C43="","","OBS-"&TEXT(ROW()-2,"000")) -> OBS-041 | C43: Marcus Thompson | D43: Portfolio Enablement Pod | E43: 2026-09-18 | F43: XPD-01 | G43: Cross-Pod Coordination | H43: Cross-pod dependencies are identified and managed too late. | I43: Marcus requests pipelines or schema changes through Slack; required work may not be on Priya's backlog, leaving his delivery waiting or forcing timeline changes. | J43: Repeated pattern | K43: DI lacks integrated roadmaps and an explicit process to surface, accept and sequence cross-pod dependencies before commitments are made. | L43: 5 | M43: High | N43: Marcus identified this as one of the two highest-priority operational issues.
...

Sheet 2_Issue Register
F2: Triangulate | K2: Prioritize | Q2: Sequencing
B3: Issue ID | C3: Issue / Gap Statement | D3: Category | E3: Root Cause Hypothesis | F3: Evidence Count | G3: Unique Sources* | H3: Strong Evidence Count | I3: Signal Strength | J3: Triangulation Confidence | K3: Business Impact (1-5) | L3: Urgency (1-5) | M3: Scale Dependency (1-5) | N3: Effort (1-5) | O3: Priority Score | P3: Priority Band | Q3: Dependency / Prerequisite | R3: Owner / Partner | S3: Readiness | T3: Suggested Sequence | U3: Final Sequence | V3: Proposed Intervention | W3: Target Outcome / Measure
B4: BVC-01 | C4: DI lacks full business-case visibility connecting material project spend to the outcomes created. | D4: Business Case & Value Management | E4: Material costs are not consistently attributed to workstreams, and success measures are not defined at intake or captured after delivery, preventing cost-to-outcome analysis. | F4: =IF(B4="","",COUNTIF('1_Evidence Log'!$F$3:$F$202,B4)) -> 4 | G4: =IF(B4="","",--(COUNTIFS('1_Evidence Log'!$F$3:$F$202,B4,'1_Evidence Log'!$C$3:$C$202,"Elena Rodriguez")>0)+--(COUNTIFS('1_Evidence Log'!$F$3:$F$202,B4,'1_Evidence Log'!$C$3:$C$202,"James Okonkwo")>0)+--(COUNTIFS('1_Evidence Log'!$F$3:$F$202,B4,'1_Evidence Log'!$C$3:$C$202,"Marcus Thompson")>0)+--(COUNTIFS('1_Evidence Log'!$F$3:$F$202,B4,'1_Evidence Log'!$C$3:$C$202,"Priya Sharma")>0)+--(COUNTIFS('1_Evidence Log'!$F$3:$F$202,B4,'1_Evidence Log'!$C$3:$C$202,"Sarah")>0)+--(COUNTIFS('1_Evidence Log'!$F$3:$F$202,B4,'1_Evidence Log'!$C$3:$C$202,"David Chen")>0)) -> 3 | H4: =IF(B4="","",COUNTIFS('1_Evidence Log'!$F$3:$F$202,B4,'1_Evidence Log'!$J$3:$J$202,"Direct example")+COUNTIFS('1_Evidence Log'!$F$3:$F$202,B4,'1_Evidence Log'!$J$3:$J$202,"Document / artifact")+COUNTIFS('1_Evidence Log'!$F$3:$F$202,B4,'1_Evidence Log'!$J$3:$J$202,"Observed behavior")+COUNTIFS('1_Evidence Log'!$F$3:$F$202,B4,'1_Evidence Log'!$J$3:$J$202,"Metric / data")) -> 0 | I4: =IF(B4="","",IF(AND(G4>=3,H4>=2),"Strong signal",IF(OR(G4>=2,H4>=1),"Emerging signal","Weak or unconfirmed"))) -> Emerging signal | J4: Medium | K4: 3 | L4: 3 | M4: 4 | N4: 4 | O4: =IF(COUNT(K4:N4)<4,"",ROUND((K4*0.35+L4*0.25+M4*0.25+(6-N4)*0.15)*20,0)) -> 62 | P4: =IF(O4="","",IF(O4>=80,"P1 — Critical",IF(O4>=65,"P2 — High",IF(O4>=50,"P3 — Medium","P4 — Longer-term")))) -> P3 — Medium | Q4: Requires stable project identifiers, material-cost tagging and credible outcome measures that avoid false precision or overstated investment causality. | R4: Director of Operations + Finance + pod leads + business sponsors | S4: Needs alignment | T4: =IF(P4="P1 — Critical","0–30 days",IF(P4="P2 — High","31–90 days","Post-90 days")) -> Post-90 days | U4: Post-90 days | V4: Add material cost ownership and expected outcome measures to intake, then review realized cost and outcomes at defined post-launch points. | W4: Material initiatives have an attributable cost, an accountable outcome owner and a defensible measure of value for prioritization and partner reporting.
B5: CAP-01 | C5: Capacity and delivery commitments are based on judgment rather than a visible workload view. | D5: Capacity Planning | E5: DI does not maintain a common view of committed work, available specialist capacity or the capacity effect of priority changes. | F5: =IF(B5="","",COUNTIF('1_Evidence Log'!$F$3:$F$202,B5)) -> 1 | G5: =IF(B5="","",--(COUNTIFS('1_Evidence Log'!$F$3:$F$202,B5,'1_Evidence Log'!$C$3:$C$202,"Elena Rodriguez")>0)+--(COUNTIFS('1_Evidence Log'!$F$3:$F$202,B5,'1_Evidence Log'!$C$3:$C$202,"James Okonkwo")>0)+--(COUNTIFS('1_Evidence Log'!$F$3:$F$202,B5,'1_Evidence Log'!$C$3:$C$202,"Marcus Thompson")>0)+--(COUNTIFS('1_Evidence Log'!$F$3:$F$202,B5,'1_Evidence Log'!$C$3:$C$202,"Priya Sharma")>0)+--(COUNTIFS('1_Evidence Log'!$F$3:$F$202,B5,'1_Evidence Log'!$C$3:$C$202,"Sarah")>0)+--(COUNTIFS('1_Evidence Log'!$F$3:$F$202,B5,'1_Evidence Log'!$C$3:$C$202,"David Chen")>0)) -> 1 | H5: =IF(B5="","",COUNTIFS('1_Evidence Log'!$F$3:$F$202,B5,'1_Evidence Log'!$J$3:$J$202,"Direct example")+COUNTIFS('1_Evidence Log'!$F$3:$F$202,B5,'1_Evidence Log'!$J$3:$J$202,"Document / artifact")+COUNTIFS('1_Evidence Log'!$F$3:$F$202,B5,'1_Evidence Log'!$J$3:$J$202,"Observed behavior")+COUNTIFS('1_Evidence Log'!$F$3:$F$202,B5,'1_Evidence Log'!$J$3:$J$202,"Metric / data")) -> 0 | I5: =IF(B5="","",IF(AND(G5>=3,H5>=2),"Strong signal",IF(OR(G5>=2,H5>=1),"Emerging signal","Weak or unconfirmed"))) -> Weak or unconfirmed | J5: Medium | K5: 5 | L5: 5 | M5: 5 | N5: 3 | O5: =IF(COUNT(K5:N5)<4,"",ROUND((K5*0.35+L5*0.25+M5*0.25+(6-N5)*0.15)*20,0)) -> 94 | P5: =IF(O5="","",IF(O5>=80,"P1 — Critical",IF(O5>=65,"P2 — High",IF(O5>=50,"P3 — Medium","P4 — Longer-term")))) -> P1 — Critical | Q5: Requires defined work categories and a deliberately lightweight approach that avoids detailed time tracking. | R5: Director of Operations + pod leads | S5: Needs alignment | T5: =IF(P5="P1 — Critical","0–30 days",IF(P5="P2 — High","31–90 days","Post-90 days")) -> 0–30 days | U5: 0–30 days | V5: Create a simple capacity view using team allocation bands, major commitments and known dependency demand. | W5: Pod leads can identify over-capacity roles and quantify the capacity displaced by a proposed priority change.
B6: CORP-01 | C6: Vendor and data-source onboarding lacks a fast, controlled end-to-end approval path. | D6: Corporate Interfaces | E6: Supplier intake has no single process owner, risk tiers, complete submission standard or visible stages, while the standard path is slow enough to encourage workarounds. | F6: =IF(B6="","",COUNTIF('1_Evidence Log'!$F$3:$F$202,B6)) -> 8 | G6: =IF(B6="","",--(COUNTIFS('1_Evidence Log'!$F$3:$F$202,B6,'1_Evidence Log'!$C$3:$C$202,"Elena Rodriguez")>0)+--(COUNTIFS('1_Evidence Log'!$F$3:$F$202,B6,'1_Evidence Log'!$C$3:$C$202,"James Okonkwo")>0)+--(COUNTIFS('1_Evidence Log'!$F$3:$F$202,B6,'1_Evidence Log'!$C$3:$C$202,"Marcus Thompson")>0)+--(COUNTIFS('1_Evidence Log'!$F$3:$F$202,B6,'1_Evidence Log'!$C$3:$C$202,"Priya Sharma")>0)+--(COUNTIFS('1_Evidence Log'!$F$3:$F$202,B6,'1_Evidence Log'!$C$3:$C$202,"Sarah")>0)+--(COUNTIFS('1_Evidence Log'!$F$3:$F$202,B6,'1_Evidence Log'!$C$3:$C$202,"David Chen")>0)) -> 5 | H6: =IF(B6="","",COUNTIFS('1_Evidence Log'!$F$3:$F$202,B6,'1_Evidence Log'!$J$3:$J$202,"Direct example")+COUNTIFS('1_Evidence Log'!$F$3:$F$202,B6,'1_Evidence Log'!$J$3:$J$202,"Document / artifact")+COUNTIFS('1_Evidence Log'!$F$3:$F$202,B6,'1_Evidence Log'!$J$3:$J$202,"Observed behavior")+COUNTIFS('1_Evidence Log'!$F$3:$F$202,B6,'1_Evidence Log'!$J$3:$J$202,"Metric / data")) -> 2 | I6: =IF(B6="","",IF(AND(G6>=3,H6>=2),"Strong signal",IF(OR(G6>=2,H6>=1),"Emerging signal","Weak or unconfirmed"))) -> Strong signal | J6: High | K6: 4 | L6: 4 | M6: 4 | N6: 3 | O6: =IF(COUNT(K6:N6)<4,"",ROUND((K6*0.35+L6*0.25+M6*0.25+(6-N6)*0.15)*20,0)) -> 77 | P6: =IF(O6="","",IF(O6>=80,"P1 — Critical",IF(O6>=65,"P2 — High",IF(O6>=50,"P3 — Medium","P4 — Longer-term")))) -> P2 — High | Q6: Scope is limited to supplier selection, diligence, contracting and pre-use approval; project and data-use review after acquisition sits under CORP-02. | R6: Director of Operations + Finance / Procurement + Legal / Compliance + Security | S6: Ready now | T6: =IF(P6="P1 — Critical","0–30 days",IF(P6="P2 — High","31–90 days","Post-90 days")) -> 31–90 days | U6: 31–60 days | V6: Create one risk-tiered intake, pre-approved paths for routine tools, standard due-diligence requirements, visible stages and service targets. | W6: All new vendors and data sources enter one workflow; routine requests follow a fast path and no tool reaches use before required reviews are complete.
B7: CORP-02 | C7: Projects, deployments and new data uses reach Legal and Compliance late and follow an opaque, overly bespoke review path. | D7: Legal & Compliance Workflow | E7: DI lacks lifecycle triggers, early roadmap visibility, standard submissions and risk-tiered review expectations for non-routine projects, deployments and data uses. | F7: =IF(B7="","",COUNTIF('1_Evidence Log'!$F$3:$F$202,B7)) -> 5 | G7: =IF(B7="","",--(COUNTIFS('1_Evidence Log'!$F$3:$F$202,B7,'1_Evidence Log'!$C$3:$C$202,"Elena Rodriguez")>0)+--(COUNTIFS('1_Evidence Log'!$F$3:$F$202,B7,'1_Evidence Log'!$C$3:$C$202,"James Okonkwo")>0)+--(COUNTIFS('1_Evidence Log'!$F$3:$F$202,B7,'1_Evidence Log'!$C$3:$C$202,"Marcus Thompson")>0)+--(COUNTIFS('1_Evidence Log'!$F$3:$F$202,B7,'1_Evidence Log'!$C$3:$C$202,"Priya Sharma")>0)+--(COUNTIFS('1_Evidence Log'!$F$3:$F$202,B7,'1_Evidence Log'!$C$3:$C$202,"Sarah")>0)+--(COUNTIFS('1_Evidence Log'!$F$3:$F$202,B7,'1_Evidence Log'!$C$3:$C$202,"David Chen")>0)) -> 4 | H7: =IF(B7="","",COUNTIFS('1_Evidence Log'!$F$3:$F$202,B7,'1_Evidence Log'!$J$3:$J$202,"Direct example")+COUNTIFS('1_Evidence Log'!$F$3:$F$202,B7,'1_Evidence Log'!$J$3:$J$202,"Document / artifact")+COUNTIFS('1_Evidence Log'!$F$3:$F$202,B7,'1_Evidence Log'!$J$3:$J$202,"Observed behavior")+COUNTIFS('1_Evidence Log'!$F$3:$F$202,B7,'1_Evidence Log'!$J$3:$J$202,"Metric / data")) -> 1 | I7: =IF(B7="","",IF(AND(G7>=3,H7>=2),"Strong signal",IF(OR(G7>=2,H7>=1),"Emerging signal","Weak or unconfirmed"))) -> Emerging signal | J7: High | K7: 4 | L7: 4 | M7: 4 | N7: 3 | O7: =IF(COUNT(K7:N7)<4,"",ROUND((K7*0.35+L7*0.25+M7*0.25+(6-N7)*0.15)*20,0)) -> 77 | P7: =IF(O7="","",IF(O7>=80,"P1 — Critical",IF(O7>=65,"P2 — High",IF(O7>=50,"P3 — Medium","P4 — Longer-term")))) -> P2 — High | Q7: Excludes supplier onboarding, which sits under CORP-01; requires confirmation of Legal versus Compliance authority and risk tiers. | R7: Director of Operations + Legal + Compliance | S7: Ready now | T7: =IF(P7="P1 — Critical","0–30 days",IF(P7="P2 — High","31–90 days","Post-90 days")) -> 31–90 days | U7: 61–90 days | V7: Embed simple risk triggers in project intake, provide standard submission templates and publish review stages and target turnaround by risk tier. | W7: Relevant work reaches reviewers during planning; DI can see status and expected timing, and routine reviews no longer require repeated translation.
B8: CORP-03 | C8: Ongoing security and data-access requests lack predictable routing, context and turnaround. | D8: Corporate Interfaces | E8: After hire onboarding, DI has no named technical interface or standard request path for project access, cloud permissions and portfolio-company enablement. | F8: =IF(B8="","",COUNTIF('1_Evidence Log'!$F$3:$F$202,B8)) -> 2 | G8: =IF(B8="","",--(COUNTIFS('1_Evidence Log'!$F$3:$F$202,B8,'1_Evidence Log'!$C$3:$C$202,"Elena Rodriguez")>0)+--(COUNTIFS('1_Evidence Log'!$F$3:$F$202,B8,'1_Evidence Log'!$C$3:$C$202,"James Okonkwo")>0)+--(COUNTIFS('1_Evidence Log'!$F$3:$F$202,B8,'1_Evidence Log'!$C$3:$C$202,"Marcus Thompson")>0)+--(COUNTIFS('1_Evidence Log'!$F$3:$F$202,B8,'1_Evidence Log'!$C$3:$C$202,"Priya Sharma")>0)+--(COUNTIFS('1_Evidence Log'!$F$3:$F$202,B8,'1_Evidence Log'!$C$3:$C$202,"Sarah")>0)+--(COUNTIFS('1_Evidence Log'!$F$3:$F$202,B8,'1_Evidence Log'!$C$3:$C$202,"David Chen")>0)) -> 2 | H8: =IF(B8="","",COUNTIFS('1_Evidence Log'!$F$3:$F$202,B8,'1_Evidence Log'!$J$3:$J$202,"Direct example")+COUNTIFS('1_Evidence Log'!$F$3:$F$202,B8,'1_Evidence Log'!$J$3:$J$202,"Document / artifact")+COUNTIFS('1_Evidence Log'!$F$3:$F$202,B8,'1_Evidence Log'!$J$3:$J$202,"Observed behavior")+COUNTIFS('1_Evidence Log'!$F$3:$F$202,B8,'1_Evidence Log'!$J$3:$J$202,"Metric / data")) -> 0 | I8: =IF(B8="","",IF(AND(G8>=3,H8>=2),"Strong signal",IF(OR(G8>=2,H8>=1),"Emerging signal","Weak or unconfirmed"))) -> Emerging signal | J8: High | K8: 4 | L8: 4 | M8: 4 | N8: 3 | O8: =IF(COUNT(K8:N8)<4,"",ROUND((K8*0.35+L8*0.25+M8*0.25+(6-N8)*0.15)*20,0)) -> 77 | P8: =IF(O8="","",IF(O8>=80,"P1 — Critical",IF(O8>=65,"P2 — High",IF(O8>=50,"P3 — Medium","P4 — Longer-term")))) -> P2 — High | Q8: Excludes new-hire provisioning, which sits under ONB-01; requires IT / SecOps capacity and separation of Deerfield versus portfolio-company steps. | R8: Director of Operations + IT / SecOps | S8: Needs alignment | T8: =IF(P8="P1 — Critical","0–30 days",IF(P8="P2 — High","31–90 days","Post-90 days")) -> 31–90 days | U8: 61–90 days | V8: Define request types, standard context, named escalation and service targets for common security and access needs. | W8: Common requests use a standard route with visible ownership and timing; baseline turnaround is measured and the largest delays have assigned fixes.
B9: DPG-01 | C9: DI lacks an explicit governance framework for sensitive data and outbound third-party data use. | D9: Data Privacy & Governance | E9: Data flows, permitted uses, external disclosures and privacy protections are not consistently documented as experiments move toward production. | F9: =IF(B9="","",COUNTIF('1_Evidence Log'!$F$3:$F$202,B9)) -> 2 | G9: =IF(B9="","",--(COUNTIFS('1_Evidence Log'!$F$3:$F$202,B9,'1_Evidence Log'!$C$3:$C$202,"Elena Rodriguez")>0)+--(COUNTIFS('1_Evidence Log'!$F$3:$F$202,B9,'1_Evidence Log'!$C$3:$C$202,"James Okonkwo")>0)+--(COUNTIFS('1_Evidence Log'!$F$3:$F$202,B9,'1_Evidence Log'!$C$3:$C$202,"Marcus Thompson")>0)+--(COUNTIFS('1_Evidence Log'!$F$3:$F$202,B9,'1_Evidence Log'!$C$3:$C$202,"Priya Sharma")>0)+--(COUNTIFS('1_Evidence Log'!$F$3:$F$202,B9,'1_Evidence Log'!$C$3:$C$202,"Sarah")>0)+--(COUNTIFS('1_Evidence Log'!$F$3:$F$202,B9,'1_Evidence Log'!$C$3:$C$202,"David Chen")>0)) -> 2 | H9: =IF(B9="","",COUNTIFS('1_Evidence Log'!$F$3:$F$202,B9,'1_Evidence Log'!$J$3:$J$202,"Direct example")+COUNTIFS('1_Evidence Log'!$F$3:$F$202,B9,'1_Evidence Log'!$J$3:$J$202,"Document / artifact")+COUNTIFS('1_Evidence Log'!$F$3:$F$202,B9,'1_Evidence Log'!$J$3:$J$202,"Observed behavior")+COUNTIFS('1_Evidence Log'!$F$3:$F$202,B9,'1_Evidence Log'!$J$3:$J$202,"Metric / data")) -> 0 | I9: =IF(B9="","",IF(AND(G9>=3,H9>=2),"Strong signal",IF(OR(G9>=2,H9>=1),"Emerging signal","Weak or unconfirmed"))) -> Emerging signal | J9: High | K9: 4 | L9: 4 | M9: 4 | N9: 3 | O9: =IF(COUNT(K9:N9)<4,"",ROUND((K9*0.35+L9*0.25+M9*0.25+(6-N9)*0.15)*20,0)) -> 77 | P9: =IF(O9="","",IF(O9>=80,"P1 — Critical",IF(O9>=65,"P2 — High",IF(O9>=50,"P3 — Medium","P4 — Longer-term")))) -> P2 — High | Q9: Requires data inventory, Compliance / Legal standards and alignment with vendor intake and model governance. | R9: Compliance / Legal + Priya + Director of Operations | S9: Needs alignment | T9: =IF(P9="P1 — Critical","0–30 days",IF(P9="P2 — High","31–90 days","Post-90 days")) -> 31–90 days | U9: Post-90 days | V9: Define data-risk tiers, sandbox-to-production triggers and minimum data-flow, rights and privacy documentation. | W9: Priority sensitive datasets have documented flows and permitted uses; new production uses cannot proceed without the required privacy and rights record.
B10: FIN-01 | C10: DI lacks a regular, driver-based financial planning process connecting roadmap, hiring, vendors and technology use to spend. | D10: Financial Planning & Spend Management | E10: Finance receives fragmented, exception-driven information because DI has no single owner for a rolling forecast and no regular mechanism to translate operating plans into financial implications. | F10: =IF(B10="","",COUNTIF('1_Evidence Log'!$F$3:$F$202,B10)) -> 6 | G10: =IF(B10="","",--(COUNTIFS('1_Evidence Log'!$F$3:$F$202,B10,'1_Evidence Log'!$C$3:$C$202,"Elena Rodriguez")>0)+--(COUNTIFS('1_Evidence Log'!$F$3:$F$202,B10,'1_Evidence Log'!$C$3:$C$202,"James Okonkwo")>0)+--(COUNTIFS('1_Evidence Log'!$F$3:$F$202,B10,'1_Evidence Log'!$C$3:$C$202,"Marcus Thompson")>0)+--(COUNTIFS('1_Evidence Log'!$F$3:$F$202,B10,'1_Evidence Log'!$C$3:$C$202,"Priya Sharma")>0)+--(COUNTIFS('1_Evidence Log'!$F$3:$F$202,B10,'1_Evidence Log'!$C$3:$C$202,"Sarah")>0)+--(COUNTIFS('1_Evidence Log'!$F$3:$F$202,B10,'1_Evidence Log'!$C$3:$C$202,"David Chen")>0)) -> 2 | H10: =IF(B10="","",COUNTIFS('1_Evidence Log'!$F$3:$F$202,B10,'1_Evidence Log'!$J$3:$J$202,"Direct example")+COUNTIFS('1_Evidence Log'!$F$3:$F$202,B10,'1_Evidence Log'!$J$3:$J$202,"Document / artifact")+COUNTIFS('1_Evidence Log'!$F$3:$F$202,B10,'1_Evidence Log'!$J$3:$J$202,"Observed behavior")+COUNTIFS('1_Evidence Log'!$F$3:$F$202,B10,'1_Evidence Log'!$J$3:$J$202,"Metric / data")) -> 2 | I10: =IF(B10="","",IF(AND(G10>=3,H10>=2),"Strong signal",IF(OR(G10>=2,H10>=1),"Emerging signal","Weak or unconfirmed"))) -> Emerging signal | J10: High | K10: 4 | L10: 4 | M10: 4 | N10: 3 | O10: =IF(COUNT(K10:N10)<4,"",ROUND((K10*0.35+L10*0.25+M10*0.25+(6-N10)*0.15)*20,0)) -> 77 | P10: =IF(O10="","",IF(O10>=80,"P1 — Critical",IF(O10>=65,"P2 — High",IF(O10>=50,"P3 — Medium","P4 — Longer-term")))) -> P2 — High | Q10: Depends on the initial portfolio view, workforce plan and vendor inventory; Finance remains the owner of firm-wide financial policy. | R10: Director of Operations + James / Finance + pod leads | S10: Needs alignment | T10: =IF(P10="P1 — Critical","0–30 days",IF(P10="P2 — High","31–90 days","Post-90 days")) -> 31–90 days | U10: 61–90 days | V10: Establish a monthly financial pulse and rolling six-month forecast linked to headcount, roadmap choices, cloud use and major vendor commitments. | W10: Finance receives 30–60 days' visibility on material changes; budget discussions use a common forecast rather than urgent invoices and retrospective explanations.
B11: FIN-02 | C11: Cloud spend is monitored too late to prevent material budget variance. | D11: Financial Planning & Spend Management | E11: Variable infrastructure consumption lacks weekly burn-rate visibility, anomaly alerts, thresholds and an accountable owner for investigation. | F11: =IF(B11="","",COUNTIF('1_Evidence Log'!$F$3:$F$202,B11)) -> 2 | G11: =IF(B11="","",--(COUNTIFS('1_Evidence Log'!$F$3:$F$202,B11,'1_Evidence Log'!$C$3:$C$202,"Elena Rodriguez")>0)+--(COUNTIFS('1_Evidence Log'!$F$3:$F$202,B11,'1_Evidence Log'!$C$3:$C$202,"James Okonkwo")>0)+--(COUNTIFS('1_Evidence Log'!$F$3:$F$202,B11,'1_Evidence Log'!$C$3:$C$202,"Marcus Thompson")>0)+--(COUNTIFS('1_Evidence Log'!$F$3:$F$202,B11,'1_Evidence Log'!$C$3:$C$202,"Priya Sharma")>0)+--(COUNTIFS('1_Evidence Log'!$F$3:$F$202,B11,'1_Evidence Log'!$C$3:$C$202,"Sarah")>0)+--(COUNTIFS('1_Evidence Log'!$F$3:$F$202,B11,'1_Evidence Log'!$C$3:$C$202,"David Chen")>0)) -> 1 | H11: =IF(B11="","",COUNTIFS('1_Evidence Log'!$F$3:$F$202,B11,'1_Evidence Log'!$J$3:$J$202,"Direct example")+COUNTIFS('1_Evidence Log'!$F$3:$F$202,B11,'1_Evidence Log'!$J$3:$J$202,"Document / artifact")+COUNTIFS('1_Evidence Log'!$F$3:$F$202,B11,'1_Evidence Log'!$J$3:$J$202,"Observed behavior")+COUNTIFS('1_Evidence Log'!$F$3:$F$202,B11,'1_Evidence Log'!$J$3:$J$202,"Metric / data")) -> 2 | I11: =IF(B11="","",IF(AND(G11>=3,H11>=2),"Strong signal",IF(OR(G11>=2,H11>=1),"Emerging signal","Weak or unconfirmed"))) -> Emerging signal | J11: Medium | K11: 4 | L11: 4 | M11: 4 | N11: 3 | O11: =IF(COUNT(K11:N11)<4,"",ROUND((K11*0.35+L11*0.25+M11*0.25+(6-N11)*0.15)*20,0)) -> 77 | P11: =IF(O11="","",IF(O11>=80,"P1 — Critical",IF(O11>=65,"P2 — High",IF(O11>=50,"P3 — Medium","P4 — Longer-term")))) -> P2 — High | Q11: Requires billing access, technical ownership and agreement on useful allocation and alert thresholds. | R11: Priya / platform owner + Director of Operations + Finance | S11: Ready now | T11: =IF(P11="P1 — Critical","0–30 days",IF(P11="P2 — High","31–90 days","Post-90 days")) -> 31–90 days | U11: 0–30 days | V11: Implement weekly cloud-cost reporting, anomaly alerts, tagged ownership and an escalation process for material variance. | W11: Cloud spend is visible during the month; material spikes trigger named follow-up within one business day and quarterly surprise variance is eliminated.
B12: HIR-01 | C12: The recruiting process is too slow and dependent on ad hoc coordination to support planned hiring volume. | D12: Hiring | E12: Once a role is approved, interview capacity is not reserved, stages run sequentially, feedback is delayed and final decisions depend heavily on David; role sequencing sits under WFP-01. | F12: =IF(B12="","",COUNTIF('1_Evidence Log'!$F$3:$F$202,B12)) -> 4 | G12: =IF(B12="","",--(COUNTIFS('1_Evidence Log'!$F$3:$F$202,B12,'1_Evidence Log'!$C$3:$C$202,"Elena Rodriguez")>0)+--(COUNTIFS('1_Evidence Log'!$F$3:$F$202,B12,'1_Evidence Log'!$C$3:$C$202,"James Okonkwo")>0)+--(COUNTIFS('1_Evidence Log'!$F$3:$F$202,B12,'1_Evidence Log'!$C$3:$C$202,"Marcus Thompson")>0)+--(COUNTIFS('1_Evidence Log'!$F$3:$F$202,B12,'1_Evidence Log'!$C$3:$C$202,"Priya Sharma")>0)+--(COUNTIFS('1_Evidence Log'!$F$3:$F$202,B12,'1_Evidence Log'!$C$3:$C$202,"Sarah")>0)+--(COUNTIFS('1_Evidence Log'!$F$3:$F$202,B12,'1_Evidence Log'!$C$3:$C$202,"David Chen")>0)) -> 2 | H12: =IF(B12="","",COUNTIFS('1_Evidence Log'!$F$3:$F$202,B12,'1_Evidence Log'!$J$3:$J$202,"Direct example")+COUNTIFS('1_Evidence Log'!$F$3:$F$202,B12,'1_Evidence Log'!$J$3:$J$202,"Document / artifact")+COUNTIFS('1_Evidence Log'!$F$3:$F$202,B12,'1_Evidence Log'!$J$3:$J$202,"Observed behavior")+COUNTIFS('1_Evidence Log'!$F$3:$F$202,B12,'1_Evidence Log'!$J$3:$J$202,"Metric / data")) -> 3 | I12: =IF(B12="","",IF(AND(G12>=3,H12>=2),"Strong signal",IF(OR(G12>=2,H12>=1),"Emerging signal","Weak or unconfirmed"))) -> Emerging signal | J12: High | K12: 5 | L12: 5 | M12: 5 | N12: 3 | O12: =IF(COUNT(K12:N12)<4,"",ROUND((K12*0.35+L12*0.25+M12*0.25+(6-N12)*0.15)*20,0)) -> 94 | P12: =IF(O12="","",IF(O12>=80,"P1 — Critical",IF(O12>=65,"P2 — High",IF(O12>=50,"P3 — Medium","P4 — Longer-term")))) -> P1 — Critical | Q12: Requires the workforce plan, clear assessment criteria and delegated decision rights by role level. | R12: Director of Operations + Elena / HR + hiring leads | S12: Ready now | T12: =IF(P12="P1 — Critical","0–30 days",IF(P12="P2 — High","31–90 days","Post-90 days")) -> 0–30 days | U12: 0–30 days | V12: Standardize requisition readiness, interview plans, reserved panels, parallel scheduling, feedback SLAs and decision authority. | W12: Every active search has a committed timeline and owner; scheduling and feedback occur within defined targets and time-to-hire begins to decline.
B13: HIR-02 | C13: Firm-wide office expectations may constrain access to specialized AI talent. | D13: Hiring | E13: DI has not defined when role scarcity and market practice justify location flexibility within Deerfield's workplace policy. | F13: =IF(B13="","",COUNTIF('1_Evidence Log'!$F$3:$F$202,B13)) -> 1 | G13: =IF(B13="","",--(COUNTIFS('1_Evidence Log'!$F$3:$F$202,B13,'1_Evidence Log'!$C$3:$C$202,"Elena Rodriguez")>0)+--(COUNTIFS('1_Evidence Log'!$F$3:$F$202,B13,'1_Evidence Log'!$C$3:$C$202,"James Okonkwo")>0)+--(COUNTIFS('1_Evidence Log'!$F$3:$F$202,B13,'1_Evidence Log'!$C$3:$C$202,"Marcus Thompson")>0)+--(COUNTIFS('1_Evidence Log'!$F$3:$F$202,B13,'1_Evidence Log'!$C$3:$C$202,"Priya Sharma")>0)+--(COUNTIFS('1_Evidence Log'!$F$3:$F$202,B13,'1_Evidence Log'!$C$3:$C$202,"Sarah")>0)+--(COUNTIFS('1_Evidence Log'!$F$3:$F$202,B13,'1_Evidence Log'!$C$3:$C$202,"David Chen")>0)) -> 1 | H13: =IF(B13="","",COUNTIFS('1_Evidence Log'!$F$3:$F$202,B13,'1_Evidence Log'!$J$3:$J$202,"Direct example")+COUNTIFS('1_Evidence Log'!$F$3:$F$202,B13,'1_Evidence Log'!$J$3:$J$202,"Document / artifact")+COUNTIFS('1_Evidence Log'!$F$3:$F$202,B13,'1_Evidence Log'!$J$3:$J$202,"Observed behavior")+COUNTIFS('1_Evidence Log'!$F$3:$F$202,B13,'1_Evidence Log'!$J$3:$J$202,"Metric / data")) -> 0 | I13: =IF(B13="","",IF(AND(G13>=3,H13>=2),"Strong signal",IF(OR(G13>=2,H13>=1),"Emerging signal","Weak or unconfirmed"))) -> Weak or unconfirmed | J13: Low | K13: 3 | L13: 2 | M13: 3 | N13: 5 | O13: =IF(COUNT(K13:N13)<4,"",ROUND((K13*0.35+L13*0.25+M13*0.25+(6-N13)*0.15)*20,0)) -> 49 | P13: =IF(O13="","",IF(O13>=80,"P1 — Critical",IF(O13>=65,"P2 — High",IF(O13>=50,"P3 — Medium","P4 — Longer-term")))) -> P4 — Longer-term | Q13: Requires evidence of candidate losses and a clear role-by-role talent-market case. | R13: David + Elena / HR + Director of Operations | S13: Needs alignment | T13: =IF(P13="P1 — Critical","0–30 days",IF(P13="P2 — High","31–90 days","Post-90 days")) -> Post-90 days | U13: Post-90 days | V13: Track location-related candidate losses and define an exception framework only if evidence supports it. | W13: DI has data on location constraints and an agreed decision rule; no policy exception is proposed without demonstrated recruiting impact.
B14: IAM-01 | C14: Access controls and information barriers are not documented or evidenced at the required level. | D14: Access & Information Barriers | E14: Policies are not consistently translated into system entitlements, periodic reviews and auditable records for sensitive research and data. | F14: =IF(B14="","",COUNTIF('1_Evidence Log'!$F$3:$F$202,B14)) -> 1 | G14: =IF(B14="","",--(COUNTIFS('1_Evidence Log'!$F$3:$F$202,B14,'1_Evidence Log'!$C$3:$C$202,"Elena Rodriguez")>0)+--(COUNTIFS('1_Evidence Log'!$F$3:$F$202,B14,'1_Evidence Log'!$C$3:$C$202,"James Okonkwo")>0)+--(COUNTIFS('1_Evidence Log'!$F$3:$F$202,B14,'1_Evidence Log'!$C$3:$C$202,"Marcus Thompson")>0)+--(COUNTIFS('1_Evidence Log'!$F$3:$F$202,B14,'1_Evidence Log'!$C$3:$C$202,"Priya Sharma")>0)+--(COUNTIFS('1_Evidence Log'!$F$3:$F$202,B14,'1_Evidence Log'!$C$3:$C$202,"Sarah")>0)+--(COUNTIFS('1_Evidence Log'!$F$3:$F$202,B14,'1_Evidence Log'!$C$3:$C$202,"David Chen")>0)) -> 1 | H14: =IF(B14="","",COUNTIFS('1_Evidence Log'!$F$3:$F$202,B14,'1_Evidence Log'!$J$3:$J$202,"Direct example")+COUNTIFS('1_Evidence Log'!$F$3:$F$202,B14,'1_Evidence Log'!$J$3:$J$202,"Document / artifact")+COUNTIFS('1_Evidence Log'!$F$3:$F$202,B14,'1_Evidence Log'!$J$3:$J$202,"Observed behavior")+COUNTIFS('1_Evidence Log'!$F$3:$F$202,B14,'1_Evidence Log'!$J$3:$J$202,"Metric / data")) -> 1 | I14: =IF(B14="","",IF(AND(G14>=3,H14>=2),"Strong signal",IF(OR(G14>=2,H14>=1),"Emerging signal","Weak or unconfirmed"))) -> Emerging signal | J14: Medium | K14: 4 | L14: 4 | M14: 4 | N14: 3 | O14: =IF(COUNT(K14:N14)<4,"",ROUND((K14*0.35+L14*0.25+M14*0.25+(6-N14)*0.15)*20,0)) -> 77 | P14: =IF(O14="","",IF(O14>=80,"P1 — Critical",IF(O14>=65,"P2 — High",IF(O14>=50,"P3 — Medium","P4 — Longer-term")))) -> P2 — High | Q14: Requires authoritative system and data inventories and ownership from IT / SecOps and Compliance. | R14: IT / SecOps + Compliance + Director of Operations | S14: Needs alignment | T14: =IF(P14="P1 — Critical","0–30 days",IF(P14="P2 — High","31–90 days","Post-90 days")) -> 31–90 days | U14: Post-90 days | V14: Create an access-control matrix for priority systems and data, assign review owners and establish evidence retention. | W14: DI can identify current access to high-risk systems and data and demonstrate review of those permissions; urgent exceptions are remediated.
B15: INT-01 | C15: DI is insufficiently integrated with the broader investment organization, weakening shared context and support for resources. | D15: DI-Deerfield Integration | E15: DI lacks deliberate stakeholder engagement and value communication beyond individual projects and requests. | F15: =IF(B15="","",COUNTIF('1_Evidence Log'!$F$3:$F$202,B15)) -> 1 | G15: =IF(B15="","",--(COUNTIFS('1_Evidence Log'!$F$3:$F$202,B15,'1_Evidence Log'!$C$3:$C$202,"Elena Rodriguez")>0)+--(COUNTIFS('1_Evidence Log'!$F$3:$F$202,B15,'1_Evidence Log'!$C$3:$C$202,"James Okonkwo")>0)+--(COUNTIFS('1_Evidence Log'!$F$3:$F$202,B15,'1_Evidence Log'!$C$3:$C$202,"Marcus Thompson")>0)+--(COUNTIFS('1_Evidence Log'!$F$3:$F$202,B15,'1_Evidence Log'!$C$3:$C$202,"Priya Sharma")>0)+--(COUNTIFS('1_Evidence Log'!$F$3:$F$202,B15,'1_Evidence Log'!$C$3:$C$202,"Sarah")>0)+--(COUNTIFS('1_Evidence Log'!$F$3:$F$202,B15,'1_Evidence Log'!$C$3:$C$202,"David Chen")>0)) -> 1 | H15: =IF(B15="","",COUNTIFS('1_Evidence Log'!$F$3:$F$202,B15,'1_Evidence Log'!$J$3:$J$202,"Direct example")+COUNTIFS('1_Evidence Log'!$F$3:$F$202,B15,'1_Evidence Log'!$J$3:$J$202,"Document / artifact")+COUNTIFS('1_Evidence Log'!$F$3:$F$202,B15,'1_Evidence Log'!$J$3:$J$202,"Observed behavior")+COUNTIFS('1_Evidence Log'!$F$3:$F$202,B15,'1_Evidence Log'!$J$3:$J$202,"Metric / data")) -> 0 | I15: =IF(B15="","",IF(AND(G15>=3,H15>=2),"Strong signal",IF(OR(G15>=2,H15>=1),"Emerging signal","Weak or unconfirmed"))) -> Weak or unconfirmed | J15: Low | K15: 3 | L15: 2 | M15: 3 | N15: 5 | O15: =IF(COUNT(K15:N15)<4,"",ROUND((K15*0.35+L15*0.25+M15*0.25+(6-N15)*0.15)*20,0)) -> 49 | P15: =IF(O15="","",IF(O15>=80,"P1 — Critical",IF(O15>=65,"P2 — High",IF(O15>=50,"P3 — Medium","P4 — Longer-term")))) -> P4 — Longer-term | Q15: Requires direct validation with Investment Partners and evidence that the perceived silo affects decisions or adoption. | R15: David + Director of Operations | S15: Needs alignment | T15: =IF(P15="P1 — Critical","0–30 days",IF(P15="P2 — High","31–90 days","Post-90 days")) -> Post-90 days | U15: Post-90 days | V15: Validate stakeholder needs and add targeted portfolio and value communication rather than a broad meeting layer. | W15: Within 90 days, partner interviews confirm whether this is a material issue and identify the smallest useful engagement mechanism.
